Workbook
Name A: #REF!
Name A: #REF!
Name A: #REF!
Name AA: #REF!
Name AA: #REF!
Name AA: #REF!
Name aaa: '[1]Sum Slots'!#REF!
Name aaa: '[1]Sum Slots'!#REF!
Name aaa: '[1]Sum Slots'!#REF!
Name AB: #REF!
Name AB: #REF!
Name AB: #REF!
Name ALL: #REF!
Name ALL: #REF!
Name ALL: #REF!
Name Allocations: #REF!
Name Allocations: #REF!
Name Allocations: #REF!
Name AvgLegSpeed: #REF!
Name AvgLegSpeed: #REF!
Name AvgLegSpeed: #REF!
Name BottomCell: '[2]WBANZ '!$V$65535
Name BSA: #REF!
Name BSA: #REF!
Name BSA: #REF!
Name bunkers: #REF!
Name bunkers: #REF!
Name bunkers: #REF!
Name Capacities: #REF!
Name Capacities: #REF!
Name Capacities: #REF!
Name Capex: '[3]Slot Cost Comparison'!#REF!
Name Capex: '[3]Slot Cost Comparison'!#REF!
Name Capex: '[3]Slot Cost Comparison'!#REF!
Name Cntrs: #REF!
Name Cntrs: #REF!
Name Cntrs: #REF!
Name CopyToBlock: TopCell:BottomCell
Name CopyToBlock: TopCell:BottomCell
Name CopyToBlock: TopCell:BottomCell
Name cost: [4]Cost!$F$6:$G$41
Name dados_export: '[5]Login RE'!#REF!
Name date: #REF!
Name date: #REF!
Name date: #REF!
Name Days: #REF!
Name Days: #REF!
Name Days: #REF!
Name debotah: TopCell:BottomCell
Name debotah: TopCell:BottomCell
Name debotah: TopCell:BottomCell
Name DRFLMCS: '[6]Vessel Particulars'!$K$46
Name DWTLMCS: '[6]Vessel Particulars'!$K$41
Name DWTMED: [7]DATA!#REF!
Name EASTABOUT: #REF!
Name EASTABOUT: #REF!
Name EASTABOUT: #REF!
Name EBDirection: #REF!
Name EBDirection: #REF!
Name EBDirection: #REF!

Sheet ABAC 2022
B3: Mercado | C3: 2011 | D3: 2012 | E3: 2013 | F3: 2014 | G3: 2015 | H3: 2016 | I3: 2017 | J3: 2018 | K3: 2019 | L3: 2020 | M3: 2021 | N3: 2022
B4: Cabotagem | C4: 285.4 | D4: 282.7 | E4: 402.3 | F4: 442.6 | G4: 448 | H4: 448.2 | I4: 507.1 | J4: 591.9 | K4: 667.8 | L4: 659.6 | M4: 695 | N4: 698.7
B5: Feeder | C5: 138.4 | D5: 262.9 | E5: 293.6 | F5: 327.7 | G5: 416.9 | H5: 417.2 | I5: 454.3 | J5: 482.8 | K5: 452 | L5: 413.3 | M5: 527.2 | N5: 552.6
B6: Total | C6: =SUM(C4:C5) -> 423.8 | D6: =SUM(D4:D5) -> 545.6 | E6: =SUM(E4:E5) -> 695.9 | F6: =SUM(F4:F5) -> 770.3 | G6: =SUM(G4:G5) -> 864.9 | H6: =SUM(H4:H5) -> 865.4 | I6: =SUM(I4:I5) -> 961.4 | J6: =SUM(J4:J5) -> 1074.7 | ... N6: =SUM(N4:N5) -> 1251.3
B8: % Variação Anual | C8: 2012 | D8: 2013 | E8: 2014 | F8: 2015 | G8: 2016 | H8: 2017 | I8: 2018 | J8: 2019 | K8: 2020 | L8: 2021 | M8: 2022
B9: % Cabotagem | C9: =D4/C4-1 -> -0.0094604064 | D9: =E4/D4-1 -> 0.42306332 | E9: =F4/E4-1 -> 0.100174 | F9: =G4/F4-1 -> 0.012200633 | G9: =H4/G4-1 -> 0.00044642857 | H9: =I4/H4-1 -> 0.13141455 | I9: =J4/I4-1 -> 0.1672254 | J9: =K4/J4-1 -> 0.12823112 | ... M9: =N4/M4-1 -> 0.005323741
B10: % Feeder | C10: =D5/C5-1 -> 0.89956647 | D10: =E5/D5-1 -> 0.11677444 | E10: =F5/E5-1 -> 0.11614441 | F10: =G5/F5-1 -> 0.27220018 | G10: =H5/G5-1 -> 0.00071959703 | H10: =I5/H5-1 -> 0.088926174 | I10: =J5/I5-1 -> 0.062733876 | J10: =K5/J5-1 -> -0.063794532 | ... M10: =N5/M5-1 -> 0.048179059
B11: % Total | C11: =D6/C6-1 -> 0.28739972 | D11: =E6/D6-1 -> 0.27547654 | E11: =F6/E6-1 -> 0.10691191 | F11: =G6/F6-1 -> 0.1228093 | G11: =H6/G6-1 -> 0.00057810151 | H11: =I6/H6-1 -> 0.11093136 | I11: =J6/I6-1 -> 0.11784897 | J11: =K6/J6-1 -> 0.0419652 | ... M11: =N6/M6-1 -> 0.023809524
B12: % PIB | C12: 0.019 | D12: 0.03 | E12: 0.005 | F12: -0.035 | G12: -0.033 | H12: 0.013 | I12: 0.018 | J12: 0.012 | K12: -0.039 | L12: 0.046 | M12: 0.031
B14: % Ano a Ano | C14: 2011 | D14: 2012 | E14: 2013 | F14: 2014 | G14: 2015 | H14: 2016 | I14: 2017 | J14: 2018 | K14: 2019 | L14: 2020 | M14: 2021 | N14: 2022
B15: % Cabotagem | C15: =C4/$C$4-1 -> 0 | D15: =D4/$C$4-1 -> -0.0094604064 | E15: =E4/$C$4-1 -> 0.40960056 | F15: =F4/$C$4-1 -> 0.55080589 | G15: =G4/$C$4-1 -> 0.5697267 | H15: =H4/$C$4-1 -> 0.57042747 | I15: =I4/$C$4-1 -> 0.77680448 | J15: =J4/$C$4-1 -> 1.0739313 | ... N15: =N4/$C$4-1 -> 1.448143
B16: % Feeder | C16: =C5/$C$5-1 -> 0 | D16: =D5/$C$5-1 -> 0.89956647 | E16: =E5/$C$5-1 -> 1.1213873 | F16: =F5/$C$5-1 -> 1.3677746 | G16: =G5/$C$5-1 -> 2.0122832 | H16: =H5/$C$5-1 -> 2.0144509 | I16: =I5/$C$5-1 -> 2.2825145 | J16: =J5/$C$5-1 -> 2.4884393 | ... N16: =N5/$C$5-1 -> 2.9927746
B17: % Total | C17: =C6/$C$6-1 -> 0 | D17: =D6/$C$6-1 -> 0.28739972 | E17: =E6/$C$6-1 -> 0.64204814 | F17: =F6/$C$6-1 -> 0.81760264 | G17: =G6/$C$6-1 -> 1.0408211 | H17: =H6/$C$6-1 -> 1.0420009 | I17: =I6/$C$6-1 -> 1.2685229 | J17: =J6/$C$6-1 -> 1.535866 | ... N17: =N6/$C$6-1 -> 1.952572

Sheet Movimentacao de Conteineres
A1: cpType | B1: (All)
A2: cpContainerType | B2: 22G1 | J2: 22G1 | K2: BRMAO | L2: BRPEC | M2: BRSUA | N2: BRSSA | O2: BRIGI | P2: BRSSZ | Q2: Total Origem | S2: Port | T2: Loading FULL | U2: Discharge FULL | V2: Loading EMPTIES | W2: Discharge EMPTIES | X2: Total Moves
A3: cpService | B3: KAB01 | J3: BRMAO | K3: =B7 -> 0 | L3: =C7 -> 63 | M3: =D7 -> 2 | N3: =E7 -> 0 | O3: =F7 -> 25 | P3: =G7 -> 95 | Q3: =SUM(K3:P3) -> 185 | S3: BRSSZ | T3: =Q35 -> 824 | U3: =P36 -> 842 | V3: =ABS(T21) -> 59 | W3: =ABS(U21)+ABS(V21) -> 41 | X3: =SUM(T3:W3) -> 1766 | AB3: =Q30*4 -> 4820
J4: BRPEC | K4: =B8 -> 28 | L4: =C8 -> 0 | M4: =D8 -> 0 | N4: =E8 -> 0 | O4: =F8 -> 20 | P4: =G8 -> 96 | Q4: =SUM(K4:P4) -> 144 | S4: BRIGI | T4: =Q34 -> 347 | U4: =O36 -> 276 | V4: =V20 -> 0 | W4: =ABS(T20)+ABS(U20) -> 71 | X4: =SUM(T4:W4) -> 694 | AB4: =Q31*4 -> 1664
A5: Sum of maxWeek | B5: Column Labels | J5: BRSUA | K5: =B9 -> 108 | L5: =C9 -> 0 | M5: =D9 -> 0 | N5: =E9 -> 0 | O5: =F9 -> 26 | P5: =G9 -> 50 | Q5: =SUM(K5:P5) -> 184 | S5: BRSSA | T5: =Q33 -> 96 | U5: =N36 -> 149 | V5: =W19 -> 53 | W5: =0 -> 0 | X5: =SUM(T5:W5) -> 298 | AB5: =Q32*4 -> 1676
A6: Row Labels | B6: BRMAO | C6: BRPEC | D6: BRSUA | E6: BRSSA | F6: BRIGI | G6: BRSSZ | H6: Grand Total | J6: BRSSA | K6: =B10 -> 2 | L6: =C10 -> 0 | M6: =D10 -> 0 | N6: =E10 -> 0 | O6: =F10 -> 0 | P6: =G10 -> 0 | Q6: =SUM(K6:P6) -> 2 | S6: BRSUA - NB | T6: =K32 -> 331 | U6: =M35+M34+M33 -> 392 | V6: =ABS(U16)-U17 -> 169 | W6: =T21+T20+T19 -> 54 | X6: =SUM(T6:W6) -> 946 | AB6: =Q33*4 -> 384
A7: BRMAO | C7: 63 | D7: 2 | F7: 25 | G7: 95 | H7: 185 | J7: BRIGI | K7: =B11 -> 19 | L7: =C11 -> 28 | M7: =D11 -> 41 | N7: =E11 -> 0 | O7: =F11 -> 0 | P7: =G11 -> 0 | Q7: =SUM(K7:P7) -> 88 | S7: BRPEC - NB | T7: =K31 -> 260 | U7: =L33+L34+L35 -> 350 | V7: =U17 -> 136 | W7: 0 | X7: =SUM(T7:W7) -> 746 | AB7: =Q34*4 -> 1388
A8: BRPEC | B8: 28 | F8: 20 | G8: 96 | H8: 144 | J8: BRSSZ | K8: =B12 -> 64 | L8: =C12 -> 29 | M8: =D12 -> 75 | N8: =E12 -> 14 | O8: =F12 -> 0 | P8: =G12 -> 0 | Q8: =SUM(K8:P8) -> 182 | S8: BRMCP | X8: =SUM(T8:W8) -> 0 | AB8: =Q35*4 -> 3296 | AD8: 2988 | AE8: =AB8-AD8 -> 308
A9: BRSUA | B9: 108 | F9: 26 | G9: 50 | H9: 184 | J9: Total Destino | K9: =SUM(K3:K8) -> 221 | L9: =SUM(L3:L8) -> 120 | M9: =SUM(M3:M8) -> 118 | N9: =SUM(N3:N8) -> 14 | O9: =SUM(O3:O8) -> 71 | P9: =SUM(P3:P8) -> 241 | Q9: =SUM(Q3:Q8) -> 785 | S9: BRMAO | T9: =Q30 -> 1205 | U9: =K36 -> 967 | V9: =T16+V16 -> 67 | W9: =ABS(U16) -> 305 | X9: =SUM(T9:W9) -> 2544 | AB9: =Q36*4 -> 13228
A10: BRSSA | B10: 2 | H10: 2 | S10: BRMCP | X10: =SUM(T10:W10) -> 0
A11: BRIGI | B11: 19 | C11: 28 | D11: 41 | H11: 88 | J11: 45G1 | K11: BRMAO | L11: BRPEC | M11: BRSUA | N11: BRSSA | O11: BRIGI | P11: BRSSZ | Q11: Total Origem | S11: BRPEC - SB | T11: =O31+P31 -> 156 | U11: =L30 -> 175 | V11: 0 | W11: =ABS(T17)+ABS(V17) -> 27 | X11: =SUM(T11:W11) -> 358 | AB11: Port | AC11: Sailing | AD11: Capacity | AE11: Utilization
A12: BRSSZ | B12: 64 | C12: 29 | D12: 75 | E12: 14 | H12: 182 | J12: BRMAO | K12: =B21 -> 0 | L12: =C21 -> 112 | M12: =D21 -> 154 | N12: =E21 -> 0 | O12: =F21 -> 201 | P12: =G21 -> 553 | Q12: =SUM(K12:P12) -> 1020 | S12: BRSUA - SB | T12: =O32+P32 -> 88 | U12: =M30+M31 -> 156 | V12: =U18-V6 -> 35 | W12: =ABS(T18)-W6+ABS(V18) -> 21 | X12: =SUM(T12:W12) -> 300 | AB12: BRSSZ | AC12: =Q44 -> 1466 | AD12: 2240 | AE12: =AC12/AD12 -> 0.65446429
A13: Grand Total | B13: 221 | C13: 120 | D13: 118 | E13: 14 | F13: 71 | G13: 241 | H13: 785 | J13: BRPEC | K13: =B22 -> 231 | L13: =C22 -> 0 | M13: =D22 -> 0 | N13: =E22 -> 0 | O13: =F22 -> 0 | P13: =G22 -> 38 | Q13: =SUM(K13:P13) -> 269 | AB13: BRIGI | AC13: =AC12-O44+Q43 -> 2072 | AD13: 2240 | AE13: =AC13/AD13 -> 0.925
J14: BRSUA | K14: =B23 -> 212 | L14: =C23 -> 0 | M14: =D23 -> 0 | N14: =E23 -> 0 | O14: =F23 -> 4 | P14: =G23 -> 7 | Q14: =SUM(K14:P14) -> 223 | AB14: BRSSA | AC14: =AC13-N43-N44+Q42 -> 1978 | AD14: 2240 | AE14: =AC14/AD14 -> 0.88303571
A15: cpType | B15: (All) | J15: BRSSA | K15: =B24 -> 82 | L15: =C24 -> 9 | M15: =D24 -> 1 | N15: =E24 -> 0 | O15: =F24 -> 0 | P15: =G24 -> 0 | Q15: =SUM(K15:P15) -> 92 | S15: IMB | T15: 22G1 | U15: 45G1 | V15: 45R1 | W15: Total | AB15: BRSUA - NB | AC15: =AC14-M42-M43-M44+K41+L41 -> 1864 | AD15: 2240 | AE15: =AC15/AD15 -> 0.83214286
A16: cpService | B16: KAB01 | J16: BRIGI | K16: =B25 -> 42 | L16: =C25 -> 92 | M16: =D25 -> 78 | N16: =E25 -> 47 | O16: =F25 -> 0 | P16: =G25 -> 0 | Q16: =SUM(K16:P16) -> 259 | S16: BRMAO | T16: =K9-Q3 -> 36 | U16: =K18-Q12 -> -305 | V16: =K27-Q21 -> 31 | W16: =ABS(T16)+ABS(U16)+ABS(V16) -> 372 | AB16: BRPEC - NB | AC16: =AC15-L42-L43-L44+K40 -> 1713 | AD16: 2240 | AE16: =AC16/AD16 -> 0.76473214
A17: cpContainerType | B17: 45G1 | J17: BRSSZ | K17: =B26 -> 148 | L17: =C26 -> 192 | M17: =D26 -> 194 | N17: =E26 -> 80 | O17: =F26 -> 0 | P17: =G26 -> 0 | Q17: =SUM(K17:P17) -> 614 | S17: BRPEC | T17: =L9-Q4 -> -24 | U17: =L18-Q13 -> 136 | V17: =L27-Q22 -> -3 | W17: =ABS(T17)+ABS(U17)+ABS(V17) -> 163 | AB17: BRMAO | AC17: =Q39 -> 2225 | AD17: 2240 | AE17: =AC17/AD17 -> 0.99330357
J18: Total Destino | K18: =SUM(K12:K17) -> 715 | L18: =SUM(L12:L17) -> 405 | M18: =SUM(M12:M17) -> 427 | N18: =SUM(N12:N17) -> 127 | O18: =SUM(O12:O17) -> 205 | P18: =SUM(P12:P17) -> 598 | Q18: =SUM(Q12:Q17) -> 2477 | S18: BRSUA | T18: =M9-Q5 -> -66 | U18: =M18-Q14 -> 204 | V18: =M27-Q23 -> -9 | W18: =ABS(T18)+ABS(U18)+ABS(V18) -> 279 | AB18: BRPEC - SB | AC18: =AC17-L39+O40+P40 -> 2134 | AD18: 2240 | AE18: =AC18/AD18 -> 0.95267857
A19: Sum of maxWeek | B19: Column Labels | S19: BRSSA | T19: =N9-Q6 -> 12 | U19: =N18-Q15 -> 35 | V19: =N27-Q24 -> 6 | W19: =ABS(T19)+ABS(U19)+ABS(V19) -> 53 | AB19: BRSUA - SB | AC19: =AC18-M39-M40+O41+P41 -> 1924 | AD19: 2240 | AE19: =AC19/AD19 -> 0.85892857
A20: Row Labels | B20: BRMAO | C20: BRPEC | D20: BRSUA | E20: BRSSA | F20: BRIGI | G20: BRSSZ | H20: Grand Total | J20: 45R1 | K20: BRMAO | L20: BRPEC | M20: BRSUA | N20: BRSSA | O20: BRIGI | P20: BRSSZ | Q20: Total Origem | S20: BRIGI | T20: =O9-Q7 -> -17 | U20: =O18-Q16 -> -54 | V20: =O27-Q25 -> 0 | W20: =ABS(T20)+ABS(U20)+ABS(V20) -> 71
A21: BRMAO | C21: 112 | D21: 154 | F21: 201 | G21: 553 | H21: 1020 | J21: BRMAO | Q21: =SUM(K21:P21) -> 0 | S21: BRSSZ | T21: =P9-Q8 -> 59 | U21: =P18-Q17 -> -16 | V21: =P27-Q26 -> -25 | W21: =ABS(T21)+ABS(U21)+ABS(V21) -> 100
A22: BRPEC | B22: 231 | G22: 38 | H22: 269 | J22: BRPEC | K22: =B35 -> 1 | P22: =E35 -> 2 | Q22: =SUM(K22:P22) -> 3 | S22: Total | T22: =SUM(T16:T21) -> 0 | U22: =SUM(U16:U21) -> 0 | V22: =SUM(V16:V21) -> 0 | W22: =SUM(W16:W21) -> 1038
A23: BRSUA | B23: 212 | F23: 4 | G23: 7 | H23: 223 | J23: BRSUA | K23: =B36 -> 11 | P23: =E36 -> 1 | Q23: =SUM(K23:P23) -> 12
A24: BRSSA | B24: 82 | C24: 9 | D24: 1 | H24: 92 | J24: BRSSA | K24: =B37 -> 2 | Q24: =SUM(K24:P24) -> 2
A25: BRIGI | B25: 42 | C25: 92 | D25: 78 | E25: 47 | H25: 259 | J25: BRIGI | Q25: =SUM(K25:P25) -> 0
A26: BRSSZ | B26: 148 | C26: 192 | D26: 194 | E26: 80 | H26: 614 | J26: BRSSZ | K26: =B38 -> 17 | M26: =C38 -> 3 | N26: =D38 -> 8 | Q26: =SUM(K26:P26) -> 28
A27: Grand Total | B27: 715 | C27: 405 | D27: 427 | E27: 127 | F27: 205 | G27: 598 | H27: 2477 | J27: Total Destino | K27: =SUM(K21:K26) -> 31 | L27: =SUM(L21:L26) -> 0 | M27: =SUM(M21:M26) -> 3 | N27: =SUM(N21:N26) -> 8 | O27: =SUM(O21:O26) -> 0 | P27: =SUM(P21:P26) -> 3 | Q27: =SUM(Q21:Q26) -> 45
A29: cpType | B29: (All) | J29: Contêineres | K29: BRMAO | L29: BRPEC | M29: BRSUA | N29: BRSSA | O29: BRIGI | P29: BRSSZ | Q29: Total Origem
A30: cpService | B30: KAB01 | J30: BRMAO | K30: =K3+K12+K21 -> 0 | L30: =L3+L12+L21 -> 175 | M30: =M3+M12+M21 -> 156 | N30: =N3+N12+N21 -> 0 | O30: =O3+O12+O21 -> 226 | P30: =P3+P12+P21 -> 648 | Q30: =SUM(K30:P30) -> 1205
A31: cpContainerType | B31: 45R1 | J31: BRPEC | K31: =K4+K13+K22 -> 260 | L31: =L4+L13+L22 -> 0 | M31: =M4+M13+M22 -> 0 | N31: =N4+N13+N22 -> 0 | O31: =O4+O13+O22 -> 20 | P31: =P4+P13+P22 -> 136 | Q31: =SUM(K31:P31) -> 416
J32: BRSUA | K32: =K5+K14+K23 -> 331 | L32: =L5+L14+L23 -> 0 | M32: =M5+M14+M23 -> 0 | N32: =N5+N14+N23 -> 0 | O32: =O5+O14+O23 -> 30 | P32: =P5+P14+P23 -> 58 | Q32: =SUM(K32:P32) -> 419
A33: Sum of maxWeek | B33: Column Labels | J33: BRSSA | K33: =K6+K15+K24 -> 86 | L33: =L6+L15+L24 -> 9 | M33: =M6+M15+M24 -> 1 | N33: =N6+N15+N24 -> 0 | O33: =O6+O15+O24 -> 0 | P33: =P6+P15+P24 -> 0 | Q33: =SUM(K33:P33) -> 96
A34: Row Labels | B34: BRMAO | C34: BRSUA | D34: BRSSA | E34: BRSSZ | F34: Grand Total | J34: BRIGI | K34: =K7+K16+K25 -> 61 | L34: =L7+L16+L25 -> 120 | M34: =M7+M16+M25 -> 119 | N34: =N7+N16+N25 -> 47 | O34: =O7+O16+O25 -> 0 | P34: =P7+P16+P25 -> 0 | Q34: =SUM(K34:P34) -> 347
A35: BRPEC | B35: 1 | C35: 0 | D35: 0 | E35: 2 | F35: 3 | J35: BRSSZ | K35: =K8+K17+K26 -> 229 | L35: =L8+L17+L26 -> 221 | M35: =M8+M17+M26 -> 272 | N35: =N8+N17+N26 -> 102 | O35: =O8+O17+O26 -> 0 | P35: =P8+P17+P26 -> 0 | Q35: =SUM(K35:P35) -> 824
A36: BRSUA | B36: 11 | C36: 0 | D36: 0 | E36: 1 | F36: 12 | J36: Total Destino | K36: =SUM(K30:K35) -> 967 | L36: =SUM(L30:L35) -> 525 | M36: =SUM(M30:M35) -> 548 | N36: =SUM(N30:N35) -> 149 | O36: =SUM(O30:O35) -> 276 | P36: =SUM(P30:P35) -> 842 | Q36: =SUM(Q30:Q35) -> 3307
A37: BRSSA | B37: 2 | C37: 0 | D37: 0 | E37: 0 | F37: 2
A38: BRSSZ | B38: 17 | C38: 3 | D38: 8 | E38: 0 | F38: 28 | J38: TEU | K38: BRMAO | L38: BRPEC | M38: BRSUA | N38: BRSSA | O38: BRIGI | P38: BRSSZ | Q38: Total Origem
A39: Grand Total | B39: 31 | C39: 3 | D39: 8 | E39: 3 | F39: 45 | J39: BRMAO | K39: =(K3+2*(K12+K21)) -> 0 | L39: =(L3+2*(L12+L21)) -> 287 | M39: =(M3+2*(M12+M21)) -> 310 | N39: =(N3+2*(N12+N21)) -> 0 | O39: =(O3+2*(O12+O21)) -> 427 | P39: =(P3+2*(P12+P21)) -> 1201 | Q39: =SUM(K39:P39) -> 2225
J40: BRPEC | K40: =(K4+2*(K13+K22)) -> 492 | L40: =(L4+2*(L13+L22)) -> 0 | M40: =(M4+2*(M13+M22)) -> 0 | N40: =(N4+2*(N13+N22)) -> 0 | O40: =(O4+2*(O13+O22)) -> 20 | P40: =(P4+2*(P13+P22)) -> 176 | Q40: =SUM(K40:P40) -> 688
J41: BRSUA | K41: =(K5+2*(K14+K23)) -> 554 | L41: =(L5+2*(L14+L23)) -> 0 | M41: =(M5+2*(M14+M23)) -> 0 | N41: =(N5+2*(N14+N23)) -> 0 | O41: =(O5+2*(O14+O23)) -> 34 | P41: =(P5+2*(P14+P23)) -> 66 | Q41: =SUM(K41:P41) -> 654
...

Sheet Distancia Rodo
B3: Cidade | C3: Porto Embarque | D3: Código do Porto | E3: Distância para Terminal de Contêineres (km) | F3: Distância para Depot (km) | G3: Distância para Terminal de Transportadora (km) | H3: Distância Rodoviária Total da Cabotagem (km) | K3: Cidade | L3: Porto Embarque | M3: Código do Porto
B4: Manaus | C4: Manaus | D4: BRMAO | E4: 10 | F4: 5 | G4: 5 | H4: =2*E4+F4+G4 -> 30 | K4: Manaus | L4: Manaus | M4: BRMAO
B5: Fortaleza | C5: Pecém | D5: BRPEC | E5: 51 | F5: 5 | G5: 5 | H5: =2*E5+F5+G5 -> 112 | K5: Fortaleza | L5: Pecém | M5: BRPEC
B6: Recife | C6: Suape | D6: BRSUA | E6: 50.3 | F6: 5 | G6: 5 | H6: =2*E6+F6+G6 -> 110.6 | K6: Recife | L6: Suape | M6: BRSUA
B7: Salvador | C7: Salvador | D7: BRSSA | E7: 12 | F7: 5 | G7: 5 | H7: =2*E7+F7+G7 -> 34 | K7: Salvador | L7: Salvador | M7: BRSSA
B8: Rio de Janeiro | C8: Itaguaí | D8: BRIGI | E8: 85.9 | F8: 5 | G8: 5 | H8: =2*E8+F8+G8 -> 181.8 | K8: Rio de Janeiro | L8: Itaguaí | M8: BRIGI
B9: São Paulo | C9: Santos | D9: BRSSZ | E9: 96 | F9: 5 | G9: 5 | H9: =2*E9+F9+G9 -> 202 | K9: São Paulo | L9: Santos | M9: BRSSZ
B11: Distâncias para o transporte de contêineres por par de portos
B13: Distâncias (km) | C13: Manaus | D13: Fortaleza | E13: Recife | F13: Salvador | G13: Rio de Janeiro | H13: São Paulo
B14: Manaus | D14: =H4+H5 -> 142 | E14: =H4+H6 -> 140.6 | F14: =H4+H7 -> 64 | G14: =H4+H8 -> 211.8 | H14: =H4+H9 -> 232
B15: Fortaleza | C15: =D14 -> 142 | E15: =H5+H6 -> 222.6 | F15: =H5+H7 -> 146 | G15: =H5+H8 -> 293.8 | H15: =H5+H9 -> 314
B16: Recife | C16: =E14 -> 140.6 | D16: =E15 -> 222.6 | F16: =H6+H7 -> 144.6 | G16: =H6+H8 -> 292.4 | H16: =H6+H9 -> 312.6
B17: Salvador | C17: =F14 -> 64 | D17: =F15 -> 146 | E17: =F16 -> 144.6 | G17: =H7+H8 -> 215.8 | H17: =+H7+H9 -> 236
B18: Rio de Janeiro | C18: =G14 -> 211.8 | D18: =G15 -> 293.8 | E18: =G16 -> 292.4 | F18: =G17 -> 215.8 | H18: =H8+H9 -> 383.8
B19: São Paulo | C19: =H14 -> 232 | D19: =H15 -> 314 | E19: =H16 -> 312.6 | F19: =H17 -> 236 | G19: =H18 -> 383.8
B21: Distância Rodoviária a partir do Google Maps
B23: Distâncias (km) | C23: Belém | D23: Fortaleza | E23: Recife | F23: Salvador | G23: Rio de Janeiro | H23: São Paulo
B24: Belém | D24: 1513 | E24: 2032 | F24: 2059 | G24: 3112 | H24: 2896
B25: Fortaleza | C25: =D24 -> 1513 | E25: 782 | F25: 1183 | G25: 2582 | H25: 3085
B26: Recife | C26: =E24 -> 2032 | D26: =E25 -> 782 | F26: 847 | G26: 2320 | H26: 2648
B27: Salvador | C27: =F24 -> 2059 | D27: =F25 -> 1183 | E27: =F26 -> 847 | G27: 1633 | H27: 1929
B28: Rio de Janeiro | C28: =G24 -> 3112 | D28: =G25 -> 2582 | E28: =G26 -> 2320 | F28: =G27 -> 1633 | H28: 434
B29: São Paulo | C29: =H24 -> 2896 | D29: =H25 -> 3085 | E29: =H26 -> 2648 | F29: =H27 -> 1929 | G29: 434
B31: Distância Rodoviária considerando 10 km de/para Terminal de Balsas em Manaus
B33: Distâncias (km) | C33: Manaus (via Belém) | D33: Fortaleza | E33: Recife | F33: Salvador | G33: Rio de Janeiro | H33: São Paulo
B34: Manaus (via Belém) | D34: =D24+10 -> 1523 | E34: =E24+10 -> 2042 | F34: =F24+10 -> 2069 | G34: =G24+10 -> 3122 | H34: =H24+10 -> 2906
B35: Fortaleza | C35: =C25+10 -> 1523 | E35: =E25 -> 782 | F35: =F25 -> 1183 | G35: =G25 -> 2582 | H35: =H25 -> 3085
B36: Recife | C36: =C26+10 -> 2042 | D36: =D26 -> 782 | F36: =F26 -> 847 | G36: =G26 -> 2320 | H36: =H26 -> 2648
B37: Salvador | C37: =C27+10 -> 2069 | D37: =D27 -> 1183 | E37: =E27 -> 847 | G37: =G27 -> 1633 | H37: =H27 -> 1929
B38: Rio de Janeiro | C38: =C28+10 -> 3122 | D38: =D28 -> 2582 | E38: =E28 -> 2320 | F38: =F28 -> 1633 | H38: =H28 -> 434
B39: São Paulo | C39: =C29+10 -> 2906 | D39: =D29 -> 3085 | E39: =E29 -> 2648 | F39: =F29 -> 1929 | G39: =G29 -> 434

Sheet Fatores Emissao
B2: Óleo Diesel - Caminhões Pesados | N2: Fatores para cálculo de CO2e
B3: Emissões Veiculares no Estado de São Paulo 2021 da CETESB
B5: Caminhões Pesados com motores do ciclo Diesel | D5: CO | E5: HC | F5: CH4 | G5: NOx | H5: MP | I5: N2O | J5: Autonomia | K5: CO2 | L5: CO2 | N5: GEE | O5: GWP (AR5)
B6: Ano | C6: Fase Proconve | D6: (g/km) | E6: (g/km) | F6: (g/km) | G6: (g/km) | H6: (g/km) | I6: (g/km) | J6: (km/l) | K6: kg/l | L6: kg/km | N6: Dióxido de Carbono (CO2) | O6: 1
B7: 2016 | C7: P7 | D7: 0.29243216 | E7: 0.032638078 | F7: 0.06 | G7: 1.6895825 | H7: 0.015589921 | I7: 0.03 | J7: 3.61 | K7: 2.603 | L7: =K7/J7 -> 0.72105263 | N7: Metano (CH4) | O7: 28
N8: Óxido Nitroso (N2O) | O8: 265
B10: Óleo Diesel - Equipamentos de Movimentação de Contêineres
B12: EPA - GHG Emission Factors Hub
C14: Gás
C15: CO2 | D15: CH4 | E15: N2O | G15: CO2 | H15: 10.21 | I15: kg/gallon
B16: Tipo | C16: kg/l | D16: (g/l) | E16: (g/l) | G16: CH4 | H16: 0.57 | I16: g/gallon
B17: Diesel | C17: =H15/H18 -> 2.6971979 | D17: =H16/H18 -> 0.15057814 | E17: =H17/H18 -> 0.068684766 | G17: N2O | H17: 0.26 | I17: g/gallon
G18: 1 Gallon | H18: 3.78541 | I18: l
G19: Density | H19: 0.85 | I19: kg/l
B23: Óleos Marítimos
B24: Fourth IMO GHG Study 2020 - Table 27 – Emissions factors used in this study for top-down estimation (unit: kg pollutant/tonne fuel)
B26: Poluente (kg /t combustível) - base 2018
B27: Poluente | C27: Tipo Combustível | D27: 2012 | E27: 2013 | F27: 2014 | G27: 2015 | H27: 2016 | I27: 2017 | J27: 2018
B28: CO2 | C28: HFO | D28: 3114 | E28: 3114 | F28: 3114 | G28: 3114 | H28: 3114 | I28: 3114 | J28: 3114
C29: MDO | D29: 3206 | E29: 3206 | F29: 3206 | G29: 3206 | H29: 3206 | I29: 3206 | J29: 3206
C30: LNG | D30: 2750 | E30: 2750 | F30: 2750 | G30: 2750 | H30: 2750 | I30: 2750 | J30: 2750
B31: CH4 | C31: HFO | D31: 0.05 | E31: 0.05 | F31: 0.05 | G31: 0.05 | H31: 0.05 | I31: 0.05 | J31: 0.05
C32: MDO | D32: 0.05 | E32: 0.05 | F32: 0.05 | G32: 0.05 | H32: 0.05 | I32: 0.05 | J32: 0.05
C33: LNG | D33: 5.31 | E33: 6 | F33: 7.35 | G33: 8.48 | H33: 10.2 | I33: 11.22 | J33: 11.96
B34: N2O | C34: HFO | D34: 0.17 | E34: 0.17 | F34: 0.17 | G34: 0.17 | H34: 0.18 | I34: 0.18 | J34: 0.18
C35: MDO | D35: 0.18 | E35: 0.18 | F35: 0.18 | G35: 0.18 | H35: 0.18 | I35: 0.18 | J35: 0.18
C36: LNG | D36: 0.08 | E36: 0.08 | F36: 0.08 | G36: 0.09 | H36: 0.09 | I36: 0.1 | J36: 0.1
B37: NOx | C37: HFO | D37: 78.61 | E37: 77.18 | F37: 76.19 | G37: 76.98 | H37: 76.71 | I37: 76.67 | J37: 75.9
C38: MDO | D38: 53.12 | E38: 52.51 | F38: 52.14 | G38: 57.68 | H38: 57.45 | I38: 57.62 | J38: 56.71
C39: LNG | D39: 5.6 | E39: 5.9 | F39: 5.82 | G39: 5.99 | H39: 7.46 | I39: 10.95 | J39: 13.44
B40: CO | C40: HFO | D40: 2.84 | E40: 2.83 | F40: 2.84 | G40: 2.86 | H40: 2.86 | I40: 2.87 | J40: 2.88
C41: MDO | D41: 2.48 | E41: 2.47 | F41: 2.47 | G41: 2.58 | H41: 2.58 | I41: 2.6 | J41: 2.59
C42: LNG | D42: 1.88 | E42: 2.07 | F42: 2.38 | G42: 2.64 | H42: 3.1 | I42: 3.57 | J42: 3.97
B43: NMVOC | C43: HFO | D43: 3.14 | E43: 3.13 | F43: 3.13 | G43: 3.17 | H43: 3.18 | I43: 3.19 | J43: 3.2
C44: MDO | D44: 2.16 | E44: 2.15 | F44: 2.15 | G44: 2.39 | H44: 2.39 | I44: 2.42 | J44: 2.4
C45: LNG | D45: 0.81 | E45: 0.88 | F45: 0.99 | G45: 1.09 | H45: 1.26 | I45: 1.44 | J45: 1.59
B46: SOx | C46: HFO | D46: 46.63 | E46: 44.8 | F46: 45.31 | G46: 47.9 | H46: 50.44 | I46: 50.83 | J46: 50.83
C47: MDO | D47: 2.74 | E47: 2.54 | F47: 2.35 | G47: 1.56 | H47: 1.56 | I47: 1.56 | J47: 1.37
C48: LNG | D48: 0.03 | E48: 0.03 | F48: 0.03 | G48: 0.03 | H48: 0.03 | I48: 0.03 | J48: 0.03
B49: PM | C49: HFO | D49: 7.11 | E49: 6.96 | F49: 7.01 | G49: 7.26 | H49: 7.48 | I49: 7.53 | J49: 7.55
...

Sheet Fatores Emissao (2)
B2: Óleo Diesel - Caminhões Pesados | N2: Fatores para cálculo de CO2e
B3: Emissões Veiculares no Estado de São Paulo 2021 da CETESB
B5: Caminhões Pesados com motores do ciclo Diesel | D5: CO | E5: HC | F5: CH4 | G5: NOx | H5: MP | I5: N2O | J5: Autonomia | K5: CO2 | L5: CO2 | N5: GEE | O5: GWP (AR5)
B6: Ano | C6: Fase Proconve | D6: (g/km) | E6: (g/km) | F6: (g/km) | G6: (g/km) | H6: (g/km) | I6: (g/km) | J6: (km/l) | K6: kg/l | L6: kg/km | N6: Dióxido de Carbono (CO2) | O6: 1
B7: até 1999 | C7: P2/P3/P4 | D7: 2.01376 | E7: 0.73621333 | F7: 0.06 | G7: 11.584533 | H7: 0.71456 | I7: 0.03 | J7: 3.45 | N7: Metano (CH4) | O7: 28
B8: 2000-2001 | C8: P3/P4 | D8: 1.8102385 | E8: 0.60341284 | F8: 0.06 | G8: 7.3191743 | H8: 0.35534312 | I8: 0.03 | J8: 3.45 | N8: Óxido Nitroso (N2O) | O8: 265
B9: 2002-2003 | C9: P4 | D9: 0.986 | E9: 0.3364 | F9: 0.06 | G9: 7.1456 | H9: 0.1392 | I9: 0.03 | J9: 3.45
B10: 2004-2005 | C10: P4/P5 | D10: 0.94 | E10: 0.25 | F10: 0.06 | G10: 6 | H10: 0.111 | I10: 0.03 | J10: 3.45
B11: 2006 | C11: P4/P5 | D11: 0.80847321 | E11: 0.21769263 | F11: 0.06 | G11: 5.2086482 | H11: 0.093560549 | I11: 0.03 | J11: 3.4482759
B12: 2007 | C12: P4/P5 | D12: 0.80847321 | E12: 0.21769263 | F12: 0.06 | G12: 5.2086482 | H12: 0.093560549 | I12: 0.03 | J12: 3.4482759
B13: 2008 | C13: P5 | D13: 0.71298621 | E13: 0.149008 | F13: 0.06 | G13: 5.3971803 | H13: 0.08539758 | I13: 0.03 | J13: 3.4482759
B14: 2009 | C14: P5 | D14: 0.90559321 | E14: 0.1166612 | F14: 0.06 | G14: 5.3488062 | H14: 0.080399024 | I14: 0.03 | J14: 3.4482759
B15: 2010 | C15: P5 | D15: 0.64286924 | E15: 0.1678739 | F15: 0.06 | G15: 5.3118644 | H15: 0.066322905 | I15: 0.03 | J15: 3.4482759
B16: 2011 | C16: P5 | D16: 0.7888196 | E16: 0.15728412 | F16: 0.06 | G16: 5.1879746 | H16: 0.071427254 | I16: 0.03 | J16: 3.4482759
B17: 2012 | C17: P7 | D17: 0.25617855 | E17: 0.029793416 | F17: 0.06 | G17: 1.5901287 | H17: 0.014981873 | I17: 0.03 | J17: 3.61
B18: 2013 | C18: P7 | D18: 0.28093545 | E18: 0.02853339 | F18: 0.06 | G18: 1.541663 | H18: 0.016157334 | I18: 0.03 | J18: 3.61
B19: 2014 | C19: P7 | D19: 0.28093545 | E19: 0.02853339 | F19: 0.06 | G19: 1.541663 | H19: 0.016157334 | I19: 0.03 | J19: 3.61
B20: 2015 | C20: P7 | D20: 0.2745322 | E20: 0.028584564 | F20: 0.06 | G20: 1.6325498 | H20: 0.016417892 | I20: 0.03 | J20: 3.61
B21: 2016 | C21: P7 | D21: 0.29243216 | E21: 0.032638078 | F21: 0.06 | G21: 1.6895825 | H21: 0.015589921 | I21: 0.03 | J21: 3.61 | K21: 2.603 | L21: =K21/J21 -> 0.72105263
B22: 2017 | C22: P7 | D22: 0.2330651 | E22: 0.024702351 | F22: 0.06 | G22: 1.6304326 | H22: 0.014045894 | I22: 0.03 | J22: 3.61
B23: 2018 | C23: P7 | D23: 0.28887895 | E23: 0.022701439 | F23: 0.06 | G23: 1.5979442 | H23: 0.014301402 | I23: 0.03 | J23: 3.61
B24: 2019 | C24: P7 | D24: 0.18626192 | E24: 0.012974946 | F24: 0.06 | G24: 1.4615692 | H24: 0.012981239 | I24: 0.03 | J24: 3.61
B25: 2020 | C25: P7 | D25: 0.19139348 | E25: 0.01275334 | F25: 0.06 | G25: 1.6482532 | H25: 0.014123316 | I25: 0.03 | J25: 3.61
B26: 2021 | C26: P7 | D26: 0.19346643 | E26: 0.01576897 | F26: 0.06 | G26: 1.571255 | H26: 0.012490735 | I26: 0.03 | J26: 3.61
B29: Óleo Diesel - Equipamentos de Movimentação de Contêineres
B31: EPA - GHG Emission Factors Hub
C33: CO2 | D33: CH4 | E33: N2O | G33: CO2 | H33: 10.21 | I33: kg/gallon
B34: Tipo | C34: kg/l | D34: (g/l) | E34: (g/l) | G34: CH4 | H34: 0.57 | I34: g/gallon
B35: Diesel | C35: =H33/H36 -> 2.6971979 | D35: =H34/H36 -> 0.15057814 | E35: =H35/H36 -> 0.068684766 | G35: N2O | H35: 0.26 | I35: g/gallon
G36: 1 Gallon | H36: 3.78541 | I36: l
G37: Density | H37: 0.85 | I37: kg/l
B41: Óleos Marítimos
B42: Fourth IMO GHG Study 2020 - Table 27 – Emissions factors used in this study for top-down estimation (unit: kg pollutant/tonne fuel)
B44: Poluente (kg /t combustível) - base 2018
B45: Poluente | C45: Tipo Combustível | D45: 2012 | E45: 2013 | F45: 2014 | G45: 2015 | H45: 2016 | I45: 2017 | J45: 2018
B46: CO2 | C46: HFO | D46: 3114 | E46: 3114 | F46: 3114 | G46: 3114 | H46: 3114 | I46: 3114 | J46: 3114
C47: MDO | D47: 3206 | E47: 3206 | F47: 3206 | G47: 3206 | H47: 3206 | I47: 3206 | J47: 3206
C48: LNG | D48: 2750 | E48: 2750 | F48: 2750 | G48: 2750 | H48: 2750 | I48: 2750 | J48: 2750
B49: CH4 | C49: HFO | D49: 0.05 | E49: 0.05 | F49: 0.05 | G49: 0.05 | H49: 0.05 | I49: 0.05 | J49: 0.05
C50: MDO | D50: 0.05 | E50: 0.05 | F50: 0.05 | G50: 0.05 | H50: 0.05 | I50: 0.05 | J50: 0.05
...

Sheet Cenarios
C3: Modal | D3: Base | E3: Cenário 1 | F3: Cenário 2 | G3: Cenário 3 | H3: Cenário 4
C4: Rodoviário Direto
C5: Modal Rodoviário | D5: Diesel | E5: GNV | F5: HVO | G5: GNV | H5: GNV
C6: Modal Hidroviário | D6: IFO | E6: IFO | F6: HVO | G6: HVO | H6: HVO
C7: Cabotagem
C8: Rodoviário Cabotagem | D8: Diesel | E8: GNV | F8: HVO | G8: GNV | H8: GNV
C9: Depot | D9: Diesel | E9: Diesel | F9: HVO | G9: HVO | H9: HVO
C10: Terminal de Contêineres | D10: Diesel | E10: Diesel | F10: HVO | G10: HVO | H10: HVO
C11: Consumo Combustíveis no Porto | D11: MDO | E11: MDO | F11: HVO | G11: LNG | H11: Metanol
C12: Praticagem e Rebocador | D12: MDO | E12: MDO | F12: HVO | G12: HVO | H12: HVO
C13: Consumo Combustíveis em Viagem | D13: VLSFO + MDO | E13: VLSFO + MDO | F13: VLSFO + HVO | G13: LNG | H13: Metanol
D15: Emissões semanais CO2e (kg)
C16: Modal | D16: Base | E16: Cenário 1 | F16: Cenário 2 | G16: Cenário 3 | H16: Cenário 4
C17: Rodoviário Direto | D17: =SUM(D18:D19) -> 7614970.5 | E17: =SUM(E18:E19) -> 6981469.6 | F17: =SUM(F18:F19) -> 7185135 | G17: =SUM(G18:G19) -> 6798985.3 | H17: =SUM(H18:H19) -> 6798985.3
C18: Modal Rodoviário | D18: ='Rodo Direto Base'!I79 -> 6025805.9 | E18: ='Rodo Direto C1'!I79 -> 5392305 | F18: ='Rodo Direto C2'!I79 -> 5778454.7 | G18: =E18 -> 5392305 | H18: =E18 -> 5392305 | L18: =E18/E17 -> 0.77237392 | M18: =F18/F17 -> 0.80422354 | N18: =G18/G17 -> 0.79310438 | O18: =H18/H17 -> 0.79310438
C19: Modal Hidroviário | D19: ='Hidroviario Base C1'!I79 -> 1589164.6 | E19: =D19 -> 1589164.6 | F19: ='Hidroviario C2'!I79 -> 1406680.3 | G19: =F19 -> 1406680.3 | H19: =G19 -> 1406680.3 | L19: =1-L18 -> 0.22762608 | M19: =1-M18 -> 0.19577646 | N19: =1-N18 -> 0.20689562 | O19: =1-O18 -> 0.20689562
C20: Cabotagem | D20: =SUM(D21:D26) -> 4159789.5 | E20: =SUM(E21:E26) -> 4103280.4 | F20: =SUM(F21:F26) -> 4121218 | G20: =SUM(G21:G26) -> 3592099.2 | H20: =SUM(H21:H26) -> 3787436
C21: Rodoviário Cabotagem | D21: ='Rodo Cabotagem Base'!I78 -> 537508.85 | E21: ='Rodo Cabotagem C1'!I78 -> 480999.83 | F21: ='Rodo Cabotagem C2'!I78 -> 515444.83 | G21: =$E$21 -> 480999.83 | H21: =$E$21 -> 480999.83
C22: Depot | D22: ='Depot Base C1'!I88 -> 19272.362 | E22: =D22 -> 19272.362 | F22: ='Depot C2'!I88 -> 18374.706 | G22: =$F$22 -> 18374.706 | H22: =$F$22 -> 18374.706
C23: Terminal de Contêineres | D23: ='TC Total'!C14 -> 67902.954 | E23: =D23 -> 67902.954 | F23: ='TC Total'!C28 -> 64740.215 | G23: =$F$23 -> 64740.215 | H23: =$F$23 -> 64740.215
C24: Consumo Combustíveis no Porto | D24: ='Navio Porto Base C1'!C203 -> 60674.461 | E24: =D24 -> 60674.461 | F24: ='Navio Porto C2'!C202 -> 56954.521 | G24: ='Navio Porto C3'!C202 -> 51591.872 | H24: ='Navio Porto C4'!C202 -> 54994.479
C25: Praticagem e Rebocador | D25: ='Praticagem e Rebocador Base C1'!C130 -> 68351.892 | E25: =D25 -> 68351.892 | F25: ='Praticagem e Rebocador C2'!C130 -> 66199.313 | G25: =$F$25 -> 66199.313 | H25: =$F$25 -> 66199.313
C26: Consumo Combustíveis em Viagem | D26: ='Navio Viagem Base C1'!C199 -> 3406078.9 | E26: =D26 -> 3406078.9 | F26: ='Navio Viagem C2'!C199 -> 3399504.4 | G26: ='Navio Viagem C3'!C198 -> 2910193.3 | H26: ='Navio Viagem C4'!C198 -> 3102127.4
D27: =D22+D23+D25 -> 155527.21 | G27: =G22+G23+G25 -> 149314.23
C28: Dif Cabotagem x Rodoviário Direto | D28: =D20/D17-1 -> -0.45373532 | E28: =E20/E17-1 -> -0.41226121 | F28: =F20/F17-1 -> -0.42642442 | G28: =G20/G17-1 -> -0.47167128 | H28: =H20/H17-1 -> -0.44294099
D31: Emissões semanais CO2e (kg)
C32: Modal | D32: Base Rodoviário | E32: Base Cabotagem | F32: Cenário 1 Rodoviário | G32: Cenário 1 Cabotagem | H32: Cenário 2 Rodoviário | I32: Cenário 2 Cabotagem | J32: Cenário 3 Rodoviário | K32: Cenário 3 Cabotagem | L32: Cenário 4 Rodoviário | M32: Cenário 4 Cabotagem
C33: Rodoviário Direto | D33: =D17 -> 7614970.5 | F33: =E17 -> 6981469.6 | H33: =F17 -> 7185135 | J33: =G17 -> 6798985.3 | L33: =H17 -> 6798985.3
C34: Modal Rodoviário | D34: =D18 -> 6025805.9 | F34: =E18 -> 5392305 | H34: =F18 -> 5778454.7 | J34: =G18 -> 5392305 | L34: =H18 -> 5392305
C35: Modal Hidroviário | D35: =D19 -> 1589164.6 | F35: =E19 -> 1589164.6 | H35: =F19 -> 1406680.3 | J35: =G19 -> 1406680.3 | L35: =H19 -> 1406680.3
C36: Cabotagem | E36: =E20 -> 4103280.4 | G36: =E20 -> 4103280.4 | I36: =F20 -> 4121218 | K36: =G20 -> 3592099.2 | M36: =H20 -> 3787436
C37: Consumo Combustíveis em Viagem | E37: =E26 -> 3406078.9 | G37: =E26 -> 3406078.9 | I37: =F26 -> 3399504.4 | K37: =G26 -> 2910193.3 | M37: =H26 -> 3102127.4
C38: Rodoviário Cabotagem | E38: =E21 -> 480999.83 | G38: =E21 -> 480999.83 | I38: =F21 -> 515444.83 | K38: =G21 -> 480999.83 | M38: =H21 -> 480999.83
C39: Praticagem e Rebocador | E39: =E25 -> 68351.892 | G39: =E25 -> 68351.892 | I39: =F25 -> 66199.313 | K39: =G25 -> 66199.313 | M39: =H25 -> 66199.313
C40: Terminal de Contêineres | E40: =E23 -> 67902.954 | G40: =E23 -> 67902.954 | I40: =F23 -> 64740.215 | K40: =G23 -> 64740.215 | M40: =H23 -> 64740.215
C41: Consumo Combustíveis no Porto | E41: =E24 -> 60674.461 | G41: =E24 -> 60674.461 | I41: =F24 -> 56954.521 | K41: =G24 -> 51591.872 | M41: =H24 -> 54994.479
C42: Depot | E42: =E22 -> 19272.362 | G42: =E22 -> 19272.362 | I42: =F22 -> 18374.706 | K42: =G22 -> 18374.706 | M42: =H22 -> 18374.706

Sheet Resumo Cenario Base
B2: Emissão Total de CO2e no Modal Rodoviário Direto por Contêiner (kg/contêiner) | J2: Emissão Semanal de CO2e do Modal Rodoviário Direto no Cenário Base (kg) | U2: Participação das Cidades na Emissão de CO2e do Modal Rodoviário no Cenário Base (%)
B3: Origem / Destino | C3: Manaus | D3: Fortaleza | E3: Recife | F3: Salvador | G3: Rio de Janeiro | H3: São Paulo | J3: Origem / Destino | K3: Manaus | L3: Fortaleza | M3: Recife | N3: Salvador | O3: Rio de Janeiro | P3: São Paulo | Q3: Total Origem CO2e (kg) | U3: Origem / Destino | V3: Manaus | W3: Fortaleza | X3: Recife | Y3: Salvador | Z3: Rio de Janeiro | AA3: São Paulo | AB3: Total Origem
B4: Manaus (via Belém) | C4: ='Rodo Direto Base'!C94+'Hidroviario Base C1'!C94 -> 0 | D4: ='Rodo Direto Base'!D94+'Hidroviario Base C1'!D94 -> 1733.8882 | E4: ='Rodo Direto Base'!E94+'Hidroviario Base C1'!E94 -> 2113.1125 | F4: ='Rodo Direto Base'!F94+'Hidroviario Base C1'!F94 -> 0 | G4: ='Rodo Direto Base'!G94+'Hidroviario Base C1'!G94 -> 2902.2497 | H4: ='Rodo Direto Base'!H94+'Hidroviario Base C1'!H94 -> 2744.4223 | J4: Manaus | K4: =C4*'Movimentacao de Conteineres'!K30 -> 0 | L4: =D4*'Movimentacao de Conteineres'!L30 -> 303430.43 | M4: =E4*'Movimentacao de Conteineres'!M30 -> 329645.54 | N4: =F4*'Movimentacao de Conteineres'!N30 -> 0 | O4: =G4*'Movimentacao de Conteineres'!O30 -> 655908.43 | P4: =H4*'Movimentacao de Conteineres'!P30 -> 1778385.6 | Q4: =SUM(K4:P4) -> 3067370 | U4: Manaus | W4: =L4/$Q$10 -> 0.039846567 | X4: =M4/$Q$10 -> 0.043289143 | Z4: =O4/$Q$10 -> 0.086134074 | AA4: =P4/$Q$10 -> 0.23353808 | AB4: =Q4/$Q$10 -> 0.40280787
B5: Fortaleza | C5: ='Rodo Direto Base'!C95+'Hidroviario Base C1'!C95 -> 1982.3116 | D5: ='Rodo Direto Base'!D95+'Hidroviario Base C1'!D95 -> 0 | E5: ='Rodo Direto Base'!E95+'Hidroviario Base C1'!E95 -> 0 | F5: ='Rodo Direto Base'!F95+'Hidroviario Base C1'!F95 -> 0 | G5: ='Rodo Direto Base'!G95+'Hidroviario Base C1'!G95 -> 1886.6226 | H5: ='Rodo Direto Base'!H95+'Hidroviario Base C1'!H95 -> 2254.1559 | J5: Fortaleza | K5: =C5*'Movimentacao de Conteineres'!K31 -> 515401.01 | L5: =D5*'Movimentacao de Conteineres'!L31 -> 0 | M5: =E5*'Movimentacao de Conteineres'!M31 -> 0 | N5: =F5*'Movimentacao de Conteineres'!N31 -> 0 | O5: =G5*'Movimentacao de Conteineres'!O31 -> 37732.451 | P5: =H5*'Movimentacao de Conteineres'!P31 -> 306565.2 | Q5: =SUM(K5:P5) -> 859698.67 | U5: Fortaleza | V5: =K5/$Q$10 -> 0.067682601 | Z5: =O5/$Q$10 -> 0.0049550357 | AA5: =P5/$Q$10 -> 0.040258226 | AB5: =Q5/$Q$10 -> 0.11289586
B6: Recife | C6: ='Rodo Direto Base'!C96+'Hidroviario Base C1'!C96 -> 2361.5359 | D6: ='Rodo Direto Base'!D96+'Hidroviario Base C1'!D96 -> 0 | E6: ='Rodo Direto Base'!E96+'Hidroviario Base C1'!E96 -> 0 | F6: ='Rodo Direto Base'!F96+'Hidroviario Base C1'!F96 -> 0 | G6: ='Rodo Direto Base'!G96+'Hidroviario Base C1'!G96 -> 1695.1837 | H6: ='Rodo Direto Base'!H96+'Hidroviario Base C1'!H96 -> 1934.8476 | J6: Recife | K6: =C6*'Movimentacao de Conteineres'!K32 -> 781668.37 | L6: =D6*'Movimentacao de Conteineres'!L32 -> 0 | M6: =E6*'Movimentacao de Conteineres'!M32 -> 0 | N6: =F6*'Movimentacao de Conteineres'!N32 -> 0 | O6: =G6*'Movimentacao de Conteineres'!O32 -> 50855.511 | P6: =H6*'Movimentacao de Conteineres'!P32 -> 112221.16 | Q6: =SUM(K6:P6) -> 944745.05 | U6: Recife | V6: =K6/$Q$10 -> 0.1026489 | Z6: =O6/$Q$10 -> 0.0066783596 | AA6: =P6/$Q$10 -> 0.014736913 | AB6: =Q6/$Q$10 -> 0.12406418
B7: Salvador | C7: ='Rodo Direto Base'!C97+'Hidroviario Base C1'!C97 -> 2381.2643 | D7: ='Rodo Direto Base'!D97+'Hidroviario Base C1'!D97 -> 864.39755 | E7: ='Rodo Direto Base'!E97+'Hidroviario Base C1'!E97 -> 618.88819 | F7: ='Rodo Direto Base'!F97+'Hidroviario Base C1'!F97 -> 0 | G7: ='Rodo Direto Base'!G97+'Hidroviario Base C1'!G97 -> 0 | H7: ='Rodo Direto Base'!H97+'Hidroviario Base C1'!H97 -> 0 | J7: Salvador | K7: =C7*'Movimentacao de Conteineres'!K33 -> 204788.73 | L7: =D7*'Movimentacao de Conteineres'!L33 -> 7779.578 | M7: =E7*'Movimentacao de Conteineres'!M33 -> 618.88819 | N7: =F7*'Movimentacao de Conteineres'!N33 -> 0 | O7: =G7*'Movimentacao de Conteineres'!O33 -> 0 | P7: =H7*'Movimentacao de Conteineres'!P33 -> 0 | Q7: =SUM(K7:P7) -> 213187.2 | U7: Salvador | V7: =K7/$Q$10 -> 0.026892912 | W7: =L7/$Q$10 -> 0.0010216163 | AB7: =Q7/$Q$10 -> 0.027995801
B8: Rio de Janeiro | C8: ='Rodo Direto Base'!C98+'Hidroviario Base C1'!C98 -> 3150.6731 | D8: ='Rodo Direto Base'!D98+'Hidroviario Base C1'!D98 -> 1886.6226 | E8: ='Rodo Direto Base'!E98+'Hidroviario Base C1'!E98 -> 1695.1837 | F8: ='Rodo Direto Base'!F98+'Hidroviario Base C1'!F98 -> 1193.2047 | G8: ='Rodo Direto Base'!G98+'Hidroviario Base C1'!G98 -> 0 | H8: ='Rodo Direto Base'!H98+'Hidroviario Base C1'!H98 -> 0 | J8: Rio de Janeiro | K8: =C8*'Movimentacao de Conteineres'!K34 -> 192191.06 | L8: =D8*'Movimentacao de Conteineres'!L34 -> 226394.71 | M8: =E8*'Movimentacao de Conteineres'!M34 -> 201726.86 | N8: =F8*'Movimentacao de Conteineres'!N34 -> 56080.623 | O8: =G8*'Movimentacao de Conteineres'!O34 -> 0 | P8: =H8*'Movimentacao de Conteineres'!P34 -> 0 | Q8: =SUM(K8:P8) -> 676393.25 | U8: Rio de Janeiro | V8: =K8/$Q$10 -> 0.025238582 | W8: =L8/$Q$10 -> 0.029730214 | X8: =M8/$Q$10 -> 0.026490826 | Y8: =N8/$Q$10 -> 0.0073645226 | AB8: =Q8/$Q$10 -> 0.088824146
B9: São Paulo | C9: ='Rodo Direto Base'!C99+'Hidroviario Base C1'!C99 -> 2992.8457 | D9: ='Rodo Direto Base'!D99+'Hidroviario Base C1'!D99 -> 2254.1559 | E9: ='Rodo Direto Base'!E99+'Hidroviario Base C1'!E99 -> 1934.8476 | F9: ='Rodo Direto Base'!F99+'Hidroviario Base C1'!F99 -> 1409.4868 | G9: ='Rodo Direto Base'!G99+'Hidroviario Base C1'!G99 -> 0 | H9: ='Rodo Direto Base'!H99+'Hidroviario Base C1'!H99 -> 0 | J9: São Paulo | K9: =C9*'Movimentacao de Conteineres'!K35 -> 685361.66 | L9: =D9*'Movimentacao de Conteineres'!L35 -> 498168.46 | M9: =E9*'Movimentacao de Conteineres'!M35 -> 526278.55 | N9: =F9*'Movimentacao de Conteineres'!N35 -> 143767.65 | O9: =G9*'Movimentacao de Conteineres'!O35 -> 0 | P9: =H9*'Movimentacao de Conteineres'!P35 -> 0 | Q9: =SUM(K9:P9) -> 1853576.3 | U9: São Paulo | V9: =K9/$Q$10 -> 0.090001879 | W9: =L9/$Q$10 -> 0.065419617 | X9: =M9/$Q$10 -> 0.069111042 | Y9: =N9/$Q$10 -> 0.018879607 | AB9: =Q9/$Q$10 -> 0.24341215
J10: Total Destino CO2e (kg) | K10: =SUM(K4:K9) -> 2379410.8 | L10: =SUM(L4:L9) -> 1035773.2 | M10: =SUM(M4:M9) -> 1058269.8 | N10: =SUM(N4:N9) -> 199848.28 | O10: =SUM(O4:O9) -> 744496.4 | P10: =SUM(P4:P9) -> 2197172 | Q10: =SUM(Q4:Q9) -> 7614970.5 | S10: =Q10*52 -> 3.9597847e+08 | U10: Total Destino | V10: =K10/$Q$10 -> 0.31246488 | W10: =L10/$Q$10 -> 0.13601802 | X10: =M10/$Q$10 -> 0.13897228 | Y10: =N10/$Q$10 -> 0.02624413 | Z10: =O10/$Q$10 -> 0.097767469 | AA10: =P10/$Q$10 -> 0.28853322 | AB10: =Q10/$Q$10 -> 1
B12: Emissão de CO2e na Cabotagem por Contêiner (kg/contêiner) | J12: Emissão de CO2e da Cabotagem no Cenário Base (kg)
B13: Origem / Destino | C13: Manaus | D13: Fortaleza | E13: Recife | F13: Salvador | G13: Rio de Janeiro | H13: São Paulo | J13: Origem / Destino | K13: Manaus | L13: Fortaleza | M13: Recife | N13: Salvador | O13: Rio de Janeiro | P13: São Paulo | Q13: Total Origem CO2e (kg)
B14: Manaus | C14: ='Cabotagem Total Base'!C6 -> 0 | D14: ='Cabotagem Total Base'!D6 -> 751.57745 | E14: ='Cabotagem Total Base'!E6 -> 960.15091 | F14: ='Cabotagem Total Base'!F6 -> 0 | G14: ='Cabotagem Total Base'!G6 -> 1705.8307 | H14: ='Cabotagem Total Base'!H6 -> 1639.4123 | J14: Manaus | K14: =C14*'Movimentacao de Conteineres'!K30 -> 0 | L14: =D14*'Movimentacao de Conteineres'!L30 -> 131526.05 | M14: =E14*'Movimentacao de Conteineres'!M30 -> 149783.54 | N14: =F14*'Movimentacao de Conteineres'!N30 -> 0 | O14: =G14*'Movimentacao de Conteineres'!O30 -> 385517.73 | P14: =H14*'Movimentacao de Conteineres'!P30 -> 1062339.2 | Q14: =SUM(K14:P14) -> 1729166.5
B15: Fortaleza | C15: ='Cabotagem Total Base'!C7 -> 1019.4831 | D15: ='Cabotagem Total Base'!D7 -> 0 | E15: ='Cabotagem Total Base'!E7 -> 0 | F15: ='Cabotagem Total Base'!F7 -> 0 | G15: ='Cabotagem Total Base'!G7 -> 1151.7539 | H15: ='Cabotagem Total Base'!H7 -> 1085.3355 | J15: Fortaleza | K15: =C15*'Movimentacao de Conteineres'!K31 -> 265065.59 | L15: =D15*'Movimentacao de Conteineres'!L31 -> 0 | M15: =E15*'Movimentacao de Conteineres'!M31 -> 0 | N15: =F15*'Movimentacao de Conteineres'!N31 -> 0 | O15: =G15*'Movimentacao de Conteineres'!O31 -> 23035.078 | P15: =H15*'Movimentacao de Conteineres'!P31 -> 147605.63 | Q15: =SUM(K15:P15) -> 435706.3
B16: Recife | C16: ='Cabotagem Total Base'!C8 -> 1255.8619 | D16: ='Cabotagem Total Base'!D8 -> 0 | E16: ='Cabotagem Total Base'!E8 -> 0 | F16: ='Cabotagem Total Base'!F8 -> 0 | G16: ='Cabotagem Total Base'!G8 -> 943.56779 | H16: ='Cabotagem Total Base'!H8 -> 877.14942 | J16: Recife | K16: =C16*'Movimentacao de Conteineres'!K32 -> 415690.28 | L16: =D16*'Movimentacao de Conteineres'!L32 -> 0 | M16: =E16*'Movimentacao de Conteineres'!M32 -> 0 | N16: =F16*'Movimentacao de Conteineres'!N32 -> 0 | O16: =G16*'Movimentacao de Conteineres'!O32 -> 28307.034 | P16: =H16*'Movimentacao de Conteineres'!P32 -> 50874.666 | Q16: =SUM(K16:P16) -> 494871.98
B17: Salvador | C17: ='Cabotagem Total Base'!C9 -> 1387.6723 | D17: ='Cabotagem Total Base'!D9 -> 567.27131 | E17: ='Cabotagem Total Base'!E9 -> 334.54948 | F17: ='Cabotagem Total Base'!F9 -> 0 | G17: ='Cabotagem Total Base'!G9 -> 0 | H17: ='Cabotagem Total Base'!H9 -> 0 | J17: Salvador | K17: =C17*'Movimentacao de Conteineres'!K33 -> 119339.82 | L17: =D17*'Movimentacao de Conteineres'!L33 -> 5105.4418 | M17: =E17*'Movimentacao de Conteineres'!M33 -> 334.54948 | N17: =F17*'Movimentacao de Conteineres'!N33 -> 0 | O17: =G17*'Movimentacao de Conteineres'!O33 -> 0 | P17: =H17*'Movimentacao de Conteineres'!P33 -> 0 | Q17: =SUM(K17:P17) -> 124779.81
B18: Rio de Janeiro | C18: ='Cabotagem Total Base'!C10 -> 1863.4901 | D18: ='Cabotagem Total Base'!D10 -> 1043.0891 | E18: ='Cabotagem Total Base'!E10 -> 810.36728 | F18: ='Cabotagem Total Base'!F10 -> 560.73522 | G18: ='Cabotagem Total Base'!G10 -> 0 | H18: ='Cabotagem Total Base'!H10 -> 0 | J18: Rio de Janeiro | K18: =C18*'Movimentacao de Conteineres'!K34 -> 113672.9 | L18: =D18*'Movimentacao de Conteineres'!L34 -> 125170.69 | M18: =E18*'Movimentacao de Conteineres'!M34 -> 96433.706 | N18: =F18*'Movimentacao de Conteineres'!N34 -> 26354.555 | O18: =G18*'Movimentacao de Conteineres'!O34 -> 0 | P18: =H18*'Movimentacao de Conteineres'!P34 -> 0 | Q18: =SUM(K18:P18) -> 361631.85
B19: São Paulo | C19: ='Cabotagem Total Base'!C11 -> 1959.068 | D19: ='Cabotagem Total Base'!D11 -> 1138.667 | E19: ='Cabotagem Total Base'!E11 -> 905.94521 | F19: ='Cabotagem Total Base'!F11 -> 656.31315 | G19: ='Cabotagem Total Base'!G11 -> 0 | H19: ='Cabotagem Total Base'!H11 -> 0 | J19: São Paulo | K19: =C19*'Movimentacao de Conteineres'!K35 -> 448626.58 | L19: =D19*'Movimentacao de Conteineres'!L35 -> 251645.42 | M19: =E19*'Movimentacao de Conteineres'!M35 -> 246417.1 | N19: =F19*'Movimentacao de Conteineres'!N35 -> 66943.941 | O19: =G19*'Movimentacao de Conteineres'!O35 -> 0 | P19: =H19*'Movimentacao de Conteineres'!P35 -> 0 | Q19: =SUM(K19:P19) -> 1013633
J20: Total Destino CO2e (kg) | K20: =SUM(K14:K19) -> 1362395.2 | L20: =SUM(L14:L19) -> 513447.6 | M20: =SUM(M14:M19) -> 492968.89 | N20: =SUM(N14:N19) -> 93298.497 | O20: =SUM(O14:O19) -> 436859.84 | P20: =SUM(P14:P19) -> 1260819.5 | Q20: =SUM(Q14:Q19) -> 4159789.5
B22: Diferença de Emissão de CO2e entre Cabotagem e Rodoviário Direto por Contêiner (kg/contêiner) | J22: Diferença de Emissão de CO2e entre Cabotagem e Rodoviário Direto (kg)
B23: Origem / Destino | C23: Manaus | D23: Fortaleza | E23: Recife | F23: Salvador | G23: Rio de Janeiro | H23: São Paulo | J23: Origem / Destino | K23: Manaus | L23: Fortaleza | M23: Recife | N23: Salvador | O23: Rio de Janeiro | P23: São Paulo | Q23: Total Origem CO2e (kg)
B24: Manaus | C24: =C14-C4 -> 0 | D24: =D14-D4 -> -982.31073 | E24: =E14-E4 -> -1152.9616 | F24: =F14-F4 -> 0 | G24: =G14-G4 -> -1196.4191 | H24: =H14-H4 -> -1105.01 | J24: Manaus | K24: =K14-K4 -> 0 | L24: =L14-L4 -> -171904.38 | M24: =M14-M4 -> -179862 | N24: =N14-N4 -> 0 | O24: =O14-O4 -> -270390.71 | P24: =P14-P4 -> -716046.46 | Q24: =SUM(K24:P24) -> -1338203.5
B25: Fortaleza | C25: =C15-C5 -> -962.82854 | D25: =D15-D5 -> 0 | E25: =E15-E5 -> 0 | F25: =F15-F5 -> 0 | G25: =G15-G5 -> -734.86866 | H25: =H15-H5 -> -1168.8204 | J25: Fortaleza | K25: =K15-K5 -> -250335.42 | L25: =L15-L5 -> 0 | M25: =M15-M5 -> 0 | N25: =N15-N5 -> 0 | O25: =O15-O5 -> -14697.373 | P25: =P15-P5 -> -158959.57 | Q25: =SUM(K25:P25) -> -423992.37
B26: Recife | C26: =C16-C6 -> -1105.674 | D26: =D16-D6 -> 0 | E26: =E16-E6 -> 0 | F26: =F16-F6 -> 0 | G26: =G16-G6 -> -751.61592 | H26: =H16-H6 -> -1057.6982 | J26: Recife | K26: =K16-K6 -> -365978.09 | L26: =L16-L6 -> 0 | M26: =M16-M6 -> 0 | N26: =N16-N6 -> 0 | O26: =O16-O6 -> -22548.478 | P26: =P16-P6 -> -61346.495 | Q26: =SUM(K26:P26) -> -449873.07
B27: Salvador | C27: =C17-C7 -> -993.59201 | D27: =D17-D7 -> -297.12624 | E27: =E17-E7 -> -284.33871 | F27: =F17-F7 -> 0 | G27: =G17-G7 -> 0 | H27: =H17-H7 -> 0 | J27: Salvador | K27: =K17-K7 -> -85448.913 | L27: =L17-L7 -> -2674.1362 | M27: =M17-M7 -> -284.33871 | N27: =N17-N7 -> 0 | O27: =O17-O7 -> 0 | P27: =P17-P7 -> 0 | Q27: =SUM(K27:P27) -> -88407.388
B28: Rio de Janeiro | C28: =C18-C8 -> -1287.183 | D28: =D18-D8 -> -843.53344 | E28: =E18-E8 -> -884.81643 | F28: =F18-F8 -> -632.46952 | G28: =G18-G8 -> 0 | H28: =H18-H8 -> 0 | J28: Rio de Janeiro | K28: =K18-K8 -> -78518.164 | L28: =L18-L8 -> -101224.01 | M28: =M18-M8 -> -105293.16 | N28: =N18-N8 -> -29726.067 | O28: =O18-O8 -> 0 | P28: =P18-P8 -> 0 | Q28: =SUM(K28:P28) -> -314761.4
B29: São Paulo | C29: =C19-C9 -> -1033.7776 | D29: =D19-D9 -> -1115.4889 | E29: =E19-E9 -> -1028.9024 | F29: =F19-F9 -> -753.17364 | G29: =G19-G9 -> 0 | H29: =H19-H9 -> 0 | J29: São Paulo | K29: =K19-K9 -> -236735.08 | L29: =L19-L9 -> -246523.04 | M29: =M19-M9 -> -279861.45 | N29: =N19-N9 -> -76823.712 | O29: =O19-O9 -> 0 | P29: =P19-P9 -> 0 | Q29: =SUM(K29:P29) -> -839943.29
J30: Total Destino CO2e (kg) | K30: =SUM(K24:K29) -> -1017015.7 | L30: =SUM(L24:L29) -> -522325.57 | M30: =SUM(M24:M29) -> -565300.95 | N30: =SUM(N24:N29) -> -106549.78 | O30: =SUM(O24:O29) -> -307636.56 | P30: =SUM(P24:P29) -> -936352.53 | Q30: =SUM(Q24:Q29) -> -3455181.1
B32: % Redução da Emissão de CO2e da Cabotagem em relação ao Rodoviário Direto por contêiner | J32: % Redução da Emissão de CO2e da Cabotagem em relação ao Modal Rodoviário
B33: Origem / Destino | C33: Manaus | D33: Fortaleza | E33: Recife | F33: Salvador | G33: Rio de Janeiro | H33: São Paulo | J33: Origem / Destino | K33: Manaus | L33: Fortaleza | M33: Recife | N33: Salvador | O33: Rio de Janeiro | P33: São Paulo | Q33: Total Origem CO2e (kg)
B34: Manaus | C34: =IF(C4=0,0,C14/C4-1) -> 0 | D34: =IF(D4=0,0,D14/D4-1) -> -0.56653638 | E34: =IF(E4=0,0,E14/E4-1) -> -0.54562243 | F34: =IF(F4=0,0,F14/F4-1) -> 0 | G34: =IF(G4=0,0,G14/G4-1) -> -0.4122385 | H34: =IF(H4=0,0,H14/H4-1) -> -0.40263847 | J34: Manaus | K34: =IF(K4=0,0,K14/K4-1) -> 0 | L34: =IF(L4=0,0,L14/L4-1) -> -0.56653638 | M34: =IF(M4=0,0,M14/M4-1) -> -0.54562243 | N34: =IF(N4=0,0,N14/N4-1) -> 0 | O34: =IF(O4=0,0,O14/O4-1) -> -0.4122385 | P34: =IF(P4=0,0,P14/P4-1) -> -0.40263847 | Q34: =IF(Q4=0,0,Q14/Q4-1) -> -0.43627066
B35: Fortaleza | C35: =IF(C5=0,0,C15/C5-1) -> -0.48570999 | D35: =IF(D5=0,0,D15/D5-1) -> 0 | E35: =IF(E5=0,0,E15/E5-1) -> 0 | F35: =IF(F5=0,0,F15/F5-1) -> 0 | G35: =IF(G5=0,0,G15/G5-1) -> -0.38951547 | H35: =IF(H5=0,0,H15/H5-1) -> -0.51851799 | J35: Fortaleza | K35: =IF(K5=0,0,K15/K5-1) -> -0.48570999 | L35: =IF(L5=0,0,L15/L5-1) -> 0 | M35: =IF(M5=0,0,M15/M5-1) -> 0 | N35: =IF(N5=0,0,N15/N5-1) -> 0 | O35: =IF(O5=0,0,O15/O5-1) -> -0.38951547 | P35: =IF(P5=0,0,P15/P5-1) -> -0.51851799 | Q35: =IF(Q5=0,0,Q15/Q5-1) -> -0.49318718
B36: Recife | C36: =IF(C6=0,0,C16/C6-1) -> -0.46820123 | D36: =IF(D6=0,0,D16/D6-1) -> 0 | E36: =IF(E6=0,0,E16/E6-1) -> 0 | F36: =IF(F6=0,0,F16/F6-1) -> 0 | G36: =IF(G6=0,0,G16/G6-1) -> -0.44338317 | H36: =IF(H6=0,0,H16/H6-1) -> -0.5466571 | J36: Recife | K36: =IF(K6=0,0,K16/K6-1) -> -0.46820123 | L36: =IF(L6=0,0,L16/L6-1) -> 0 | M36: =IF(M6=0,0,M16/M6-1) -> 0 | N36: =IF(N6=0,0,N16/N6-1) -> 0 | O36: =IF(O6=0,0,O16/O6-1) -> -0.44338317 | P36: =IF(P6=0,0,P16/P6-1) -> -0.5466571 | Q36: =IF(Q6=0,0,Q16/Q6-1) -> -0.47618463
B37: Salvador | C37: =IF(C7=0,0,C17/C7-1) -> -0.41725398 | D37: =IF(D7=0,0,D17/D7-1) -> -0.34373795 | E37: =IF(E7=0,0,E17/E7-1) -> -0.45943471 | F37: =IF(F7=0,0,F17/F7-1) -> 0 | G37: =IF(G7=0,0,G17/G7-1) -> 0 | H37: =IF(H7=0,0,H17/H7-1) -> 0 | J37: Salvador | K37: =IF(K7=0,0,K17/K7-1) -> -0.41725398 | L37: =IF(L7=0,0,L17/L7-1) -> -0.34373795 | M37: =IF(M7=0,0,M17/M7-1) -> -0.45943471 | N37: =IF(N7=0,0,N17/N7-1) -> 0 | O37: =IF(O7=0,0,O17/O7-1) -> 0 | P37: =IF(P7=0,0,P17/P7-1) -> 0 | Q37: =IF(Q7=0,0,Q17/Q7-1) -> -0.4146937
B38: Rio de Janeiro | C38: =IF(C8=0,0,C18/C8-1) -> -0.40854223 | D38: =IF(D8=0,0,D18/D8-1) -> -0.44711299 | E38: =IF(E8=0,0,E18/E8-1) -> -0.52195902 | F38: =IF(F8=0,0,F18/F8-1) -> -0.53005951 | G38: =IF(G8=0,0,G18/G8-1) -> 0 | H38: =IF(H8=0,0,H18/H8-1) -> 0 | J38: Rio de Janeiro | K38: =IF(K8=0,0,K18/K8-1) -> -0.40854223 | L38: =IF(L8=0,0,L18/L8-1) -> -0.44711299 | M38: =IF(M8=0,0,M18/M8-1) -> -0.52195902 | N38: =IF(N8=0,0,N18/N8-1) -> -0.53005951 | O38: =IF(O8=0,0,O18/O8-1) -> 0 | P38: =IF(P8=0,0,P18/P8-1) -> 0 | Q38: =IF(Q8=0,0,Q18/Q8-1) -> -0.46535266
B39: São Paulo | C39: =IF(C9=0,0,C19/C9-1) -> -0.34541629 | D39: =IF(D9=0,0,D19/D9-1) -> -0.49485879 | E39: =IF(E9=0,0,E19/E9-1) -> -0.53177439 | F39: =IF(F9=0,0,F19/F9-1) -> -0.5343602 | G39: =IF(G9=0,0,G19/G9-1) -> 0 | H39: =IF(H9=0,0,H19/H9-1) -> 0 | J39: São Paulo | K39: =IF(K9=0,0,K19/K9-1) -> -0.34541629 | L39: =IF(L9=0,0,L19/L9-1) -> -0.49485879 | M39: =IF(M9=0,0,M19/M9-1) -> -0.53177439 | N39: =IF(N9=0,0,N19/N9-1) -> -0.5343602 | O39: =IF(O9=0,0,O19/O9-1) -> 0 | P39: =IF(P9=0,0,P19/P9-1) -> 0 | Q39: =IF(Q9=0,0,Q19/Q9-1) -> -0.4531474
J40: Total Destino | K40: =IF(K10=0,0,K20/K10-1) -> -0.42742332 | L40: =IF(L10=0,0,L20/L10-1) -> -0.50428567 | M40: =IF(M10=0,0,M20/M10-1) -> -0.53417467 | N40: =IF(N10=0,0,N20/N10-1) -> -0.53315336 | O40: =IF(O10=0,0,O20/O10-1) -> -0.4132143 | P40: =IF(P10=0,0,P20/P10-1) -> -0.4261626 | Q40: =IF(Q10=0,0,Q20/Q10-1) -> -0.45373532
B45: Emissão de CO2e | C45: CO2e (kg) | D45: %
B46: Rodoviário Direto | C46: =Q10 -> 7614970.5 | D46: 1
B47: Cabotagem | C47: =Q20 -> 4159789.5 | D47: 1
B48: Rodoviário | C48: ='Rodo Cabotagem Base'!I78 -> 537508.85 | D48: =C48/$C$47 -> 0.1292154
...

Sheet Hidroviario Base C1
B2: Transporte por Balsas Manaus - Belém (fonte - J.F de Oliveira Navegação Ltda)
B4: Dados Operacionais
B5: Comboio | C5: 1 Empurrador com 2 balsas
B6: Carretas | C6: 120
B7: Combustível | C7: IFO
B8: Consumo (l/h) | C8: 209.5 | D8: l/h
B9: Conversão l para t | C9: 1067 | D9: l/t
B10: Consumo (t/h) | C10: =C8/C9 -> 0.19634489 | D10: t/h
B11: Viagem Manaus - Belém | C11: 5 | D11: dia
B12: Viagem Belém - Manaus | C12: 7 | D12: dias
B14: Consumo IFO por Carreta | C14: t/carreta
B15: Viagem Manaus - Belém | C15: =$C$10*C11*24/$C$6 -> 0.19634489
B16: Viagem Belém - Manaus | C16: =$C$10*C12*24/$C$6 -> 0.27488285
B18: Transporte Semanal | C18: BRMAO | D18: BRPEC | E18: BRSUA | F18: BRSSA | G18: BRIGI | H18: BRSSZ | I18: Total Origem
B19: BRMAO | C19: ='Movimentacao de Conteineres'!K30 -> 0 | D19: ='Movimentacao de Conteineres'!L30 -> 175 | E19: ='Movimentacao de Conteineres'!M30 -> 156 | F19: ='Movimentacao de Conteineres'!N30 -> 0 | G19: ='Movimentacao de Conteineres'!O30 -> 226 | H19: ='Movimentacao de Conteineres'!P30 -> 648 | I19: =SUM(C19:H19) -> 1205
B20: BRPEC | C20: ='Movimentacao de Conteineres'!K31 -> 260 | D20: ='Movimentacao de Conteineres'!L31 -> 0 | E20: ='Movimentacao de Conteineres'!M31 -> 0 | F20: ='Movimentacao de Conteineres'!N31 -> 0 | G20: ='Movimentacao de Conteineres'!O31 -> 20 | H20: ='Movimentacao de Conteineres'!P31 -> 136 | I20: =SUM(C20:H20) -> 416
B21: BRSUA | C21: ='Movimentacao de Conteineres'!K32 -> 331 | D21: ='Movimentacao de Conteineres'!L32 -> 0 | E21: ='Movimentacao de Conteineres'!M32 -> 0 | F21: ='Movimentacao de Conteineres'!N32 -> 0 | G21: ='Movimentacao de Conteineres'!O32 -> 30 | H21: ='Movimentacao de Conteineres'!P32 -> 58 | I21: =SUM(C21:H21) -> 419
B22: BRSSA | C22: ='Movimentacao de Conteineres'!K33 -> 86 | D22: ='Movimentacao de Conteineres'!L33 -> 9 | E22: ='Movimentacao de Conteineres'!M33 -> 1 | F22: ='Movimentacao de Conteineres'!N33 -> 0 | G22: ='Movimentacao de Conteineres'!O33 -> 0 | H22: ='Movimentacao de Conteineres'!P33 -> 0 | I22: =SUM(C22:H22) -> 96
B23: BRIGI | C23: ='Movimentacao de Conteineres'!K34 -> 61 | D23: ='Movimentacao de Conteineres'!L34 -> 120 | E23: ='Movimentacao de Conteineres'!M34 -> 119 | F23: ='Movimentacao de Conteineres'!N34 -> 47 | G23: ='Movimentacao de Conteineres'!O34 -> 0 | H23: ='Movimentacao de Conteineres'!P34 -> 0 | I23: =SUM(C23:H23) -> 347
B24: BRSSZ | C24: ='Movimentacao de Conteineres'!K35 -> 229 | D24: ='Movimentacao de Conteineres'!L35 -> 221 | E24: ='Movimentacao de Conteineres'!M35 -> 272 | F24: ='Movimentacao de Conteineres'!N35 -> 102 | G24: ='Movimentacao de Conteineres'!O35 -> 0 | H24: ='Movimentacao de Conteineres'!P35 -> 0 | I24: =SUM(C24:H24) -> 824
B25: Total Destino | C25: =SUM(C19:C24) -> 967 | D25: =SUM(D19:D24) -> 525 | E25: =SUM(E19:E24) -> 548 | F25: =SUM(F19:F24) -> 149 | G25: =SUM(G19:G24) -> 276 | H25: =SUM(H19:H24) -> 842 | I25: =SUM(I19:I24) -> 3307
B29: Cálculo das Emissões - IFO
B31: Fator de emissão de CO2 modal Hidroviário | E31: ='Fatores Emissao'!C62 -> 3114 | F31: kg / t IFO
B32: Emissão de CO2 (kg) | C32: Manaus (via Belém) | D32: Fortaleza | E32: Recife | F32: Salvador | G32: Rio de Janeiro | H32: São Paulo | I32: Total Origem CO2 (kg)
B33: Manaus (via Belém) | D33: =D19*$C$15*$E$31 -> 106998.15 | E33: =E19*$C$15*$E$31 -> 95381.207 | F33: =F19*$C$15*$E$31 -> 0 | G33: =G19*$C$15*$E$31 -> 138180.47 | H33: =H19*$C$15*$E$31 -> 396198.86 | I33: =SUM(C33:H33) -> 736758.68
B34: Fortaleza | C34: =C20*$C$16*$E$31 -> 222556.15 | E34: ='Rodo Direto Base'!N21*'Rodo Direto Base'!$E$31 -> 0 | F34: ='Rodo Direto Base'!O21*'Rodo Direto Base'!$E$31 -> 0 | G34: ='Rodo Direto Base'!P21*'Rodo Direto Base'!$E$31 -> 0 | H34: ='Rodo Direto Base'!Q21*'Rodo Direto Base'!$E$31 -> 0 | I34: =SUM(C34:H34) -> 222556.15
B35: Recife | C35: =C21*$C$16*$E$31 -> 283331.1 | D35: ='Rodo Direto Base'!M22*'Rodo Direto Base'!$E$31 -> 0 | F35: ='Rodo Direto Base'!O22*'Rodo Direto Base'!$E$31 -> 0 | G35: ='Rodo Direto Base'!P22*'Rodo Direto Base'!$E$31 -> 0 | H35: ='Rodo Direto Base'!Q22*'Rodo Direto Base'!$E$31 -> 0 | I35: =SUM(C35:H35) -> 283331.1
B36: Salvador | C36: =C22*$C$16*$E$31 -> 73614.727 | D36: ='Rodo Direto Base'!M23*'Rodo Direto Base'!$E$31 -> 0 | E36: ='Rodo Direto Base'!N23*'Rodo Direto Base'!$E$31 -> 0 | G36: ='Rodo Direto Base'!P23*'Rodo Direto Base'!$E$31 -> 0 | H36: ='Rodo Direto Base'!Q23*'Rodo Direto Base'!$E$31 -> 0 | I36: =SUM(C36:H36) -> 73614.727
B37: Rio de Janeiro | C37: =C23*$C$16*$E$31 -> 52215.097 | D37: ='Rodo Direto Base'!M24*'Rodo Direto Base'!$E$31 -> 0 | E37: ='Rodo Direto Base'!N24*'Rodo Direto Base'!$E$31 -> 0 | F37: ='Rodo Direto Base'!O24*'Rodo Direto Base'!$E$31 -> 0 | H37: ='Rodo Direto Base'!Q24*'Rodo Direto Base'!$E$31 -> 0 | I37: =SUM(C37:H37) -> 52215.097
B38: São Paulo | C38: =C24*$C$16*$E$31 -> 196020.61 | D38: ='Rodo Direto Base'!M25*'Rodo Direto Base'!$E$31 -> 0 | E38: ='Rodo Direto Base'!N25*'Rodo Direto Base'!$E$31 -> 0 | F38: ='Rodo Direto Base'!O25*'Rodo Direto Base'!$E$31 -> 0 | G38: ='Rodo Direto Base'!P25*'Rodo Direto Base'!$E$31 -> 0 | I38: =SUM(C38:H38) -> 196020.61
B39: Total Destino CO2 (kg) | C39: =SUM(C33:C38) -> 827737.68 | D39: =SUM(D33:D38) -> 106998.15 | E39: =SUM(E33:E38) -> 95381.207 | F39: =SUM(F33:F38) -> 0 | G39: =SUM(G33:G38) -> 138180.47 | H39: =SUM(H33:H38) -> 396198.86 | I39: =SUM(I33:I38) -> 1564496.4
B42: Fator de emissão de CH4 modal Hidroviário | E42: ='Fatores Emissao'!D62 -> 0.05 | F42: kg / t IFO
B43: Emissão de CH4 (kg) | C43: Manaus (via Belém) | D43: Fortaleza | E43: Recife | F43: Salvador | G43: Rio de Janeiro | H43: São Paulo | I43: Total Origem CH4 (kg)
B44: Manaus (via Belém) | D44: =D19*$C$15*$E$42 -> 1.7180178 | E44: =E19*$C$15*$E$42 -> 1.5314902 | F44: =F19*$C$15*$E$42 -> 0 | G44: =G19*$C$15*$E$42 -> 2.2186973 | H44: =H19*$C$15*$E$42 -> 6.3615745 | I44: =SUM(C44:H44) -> 11.82978
B45: Fortaleza | C45: =C20*$C$16*$E$42 -> 3.573477 | E45: =E34*'Rodo Direto Base'!$E$31 -> 0 | F45: =F34*'Rodo Direto Base'!$E$31 -> 0 | G45: =G34*'Rodo Direto Base'!$E$31 -> 0 | H45: =H34*'Rodo Direto Base'!$E$31 -> 0 | I45: =SUM(C45:H45) -> 3.573477
B46: Recife | C46: =C21*$C$16*$E$42 -> 4.5493112 | D46: =D35*'Rodo Direto Base'!$E$31 -> 0 | F46: =F35*'Rodo Direto Base'!$E$31 -> 0 | G46: =G35*'Rodo Direto Base'!$E$31 -> 0 | H46: =H35*'Rodo Direto Base'!$E$31 -> 0 | I46: =SUM(C46:H46) -> 4.5493112
B47: Salvador | C47: =C22*$C$16*$E$42 -> 1.1819963 | D47: =D36*'Rodo Direto Base'!$E$31 -> 0 | E47: =E36*'Rodo Direto Base'!$E$31 -> 0 | G47: =G36*'Rodo Direto Base'!$E$31 -> 0 | H47: =H36*'Rodo Direto Base'!$E$31 -> 0 | I47: =SUM(C47:H47) -> 1.1819963
B48: Rio de Janeiro | C48: =C23*$C$16*$E$42 -> 0.83839269 | D48: =D37*'Rodo Direto Base'!$E$31 -> 0 | E48: =E37*'Rodo Direto Base'!$E$31 -> 0 | F48: =F37*'Rodo Direto Base'!$E$31 -> 0 | H48: =H37*'Rodo Direto Base'!$E$31 -> 0 | I48: =SUM(C48:H48) -> 0.83839269
B49: São Paulo | C49: =C24*$C$16*$E$42 -> 3.1474086 | D49: =D38*'Rodo Direto Base'!$E$31 -> 0 | E49: =E38*'Rodo Direto Base'!$E$31 -> 0 | F49: =F38*'Rodo Direto Base'!$E$31 -> 0 | G49: =G38*'Rodo Direto Base'!$E$31 -> 0 | I49: =SUM(C49:H49) -> 3.1474086
B50: Total Destino CH4 (kg) | C50: =SUM(C44:C49) -> 13.290586 | D50: =SUM(D44:D49) -> 1.7180178 | E50: =SUM(E44:E49) -> 1.5314902 | F50: =SUM(F44:F49) -> 0 | G50: =SUM(G44:G49) -> 2.2186973 | H50: =SUM(H44:H49) -> 6.3615745 | I50: =SUM(I44:I49) -> 25.120366
...

Sheet Hidroviario C2
B2: Transporte por Balsas Manaus - Belém (fonte - J.F de Oliveira Navegação Ltda)
B4: Dados Operacionais
B5: Comboio | C5: 1 Empurrador com 2 balsas
B6: Carretas | C6: 120
B7: Combustível | C7: HVO
B8: Consumo (l/h) | C8: 209.5 | D8: l/h
B9: Conversão l para t | C9: 1067 | D9: l/t
B10: Consumo (t/h) | C10: =C8/C9 -> 0.19634489 | D10: t/h
B11: Viagem Manaus - Belém | C11: 5 | D11: dia
B12: Viagem Belém - Manaus | C12: 7 | D12: dias
B14: Consumo Biodiesel por Carreta | C14: t/carreta
B15: Viagem Manaus - Belém | C15: =$C$10*C11*24/$C$6*'Fatores Emissao'!C95/'Fatores Emissao'!C97 -> 0.19206151
B16: Viagem Belém - Manaus | C16: =$C$10*C12*24/$C$6*'Fatores Emissao'!C95/'Fatores Emissao'!C97 -> 0.26888611
B18: Transporte Semanal | C18: BRMAO | D18: BRPEC | E18: BRSUA | F18: BRSSA | G18: BRIGI | H18: BRSSZ | I18: Total Origem
B19: BRMAO | C19: ='Movimentacao de Conteineres'!K30 -> 0 | D19: ='Movimentacao de Conteineres'!L30 -> 175 | E19: ='Movimentacao de Conteineres'!M30 -> 156 | F19: ='Movimentacao de Conteineres'!N30 -> 0 | G19: ='Movimentacao de Conteineres'!O30 -> 226 | H19: ='Movimentacao de Conteineres'!P30 -> 648 | I19: =SUM(C19:H19) -> 1205
B20: BRPEC | C20: ='Movimentacao de Conteineres'!K31 -> 260 | D20: ='Movimentacao de Conteineres'!L31 -> 0 | E20: ='Movimentacao de Conteineres'!M31 -> 0 | F20: ='Movimentacao de Conteineres'!N31 -> 0 | G20: ='Movimentacao de Conteineres'!O31 -> 20 | H20: ='Movimentacao de Conteineres'!P31 -> 136 | I20: =SUM(C20:H20) -> 416
B21: BRSUA | C21: ='Movimentacao de Conteineres'!K32 -> 331 | D21: ='Movimentacao de Conteineres'!L32 -> 0 | E21: ='Movimentacao de Conteineres'!M32 -> 0 | F21: ='Movimentacao de Conteineres'!N32 -> 0 | G21: ='Movimentacao de Conteineres'!O32 -> 30 | H21: ='Movimentacao de Conteineres'!P32 -> 58 | I21: =SUM(C21:H21) -> 419
B22: BRSSA | C22: ='Movimentacao de Conteineres'!K33 -> 86 | D22: ='Movimentacao de Conteineres'!L33 -> 9 | E22: ='Movimentacao de Conteineres'!M33 -> 1 | F22: ='Movimentacao de Conteineres'!N33 -> 0 | G22: ='Movimentacao de Conteineres'!O33 -> 0 | H22: ='Movimentacao de Conteineres'!P33 -> 0 | I22: =SUM(C22:H22) -> 96
